Workbook
Name ActualNumberOfPayments: IFERROR(IF('Loan Summary '!LoanIsGood,IF('Loan Summary '!PaymentsPerYear=1,1,MATCH(0.01,'Loan Summary '!End_Bal,-1)+1)),"")
Name ColumnTitle1: #REF!
Name End_Bal: #REF!
Name ExtraPayments: 'Loan Summary '!#REF!
Name InterestRate: 'Loan Summary '!$E$6
Name LastCol: MATCH(REPT("z",255),'Loan Summary '!$13:$13)
Name LastCol: MATCH(REPT("z",255),#REF!)
Name LastRow: MATCH(9.99E+307,'Loan Summary '!$B:$B)
Name LastRow: MATCH(9.99E+307,#REF!)
Name LenderName: 'Loan Summary '!#REF!
Name LoanAmount: 'Loan Summary '!$E$5
Name LoanIsGood: ('Loan Summary '!$E$5*'Loan Summary '!$E$6*'Loan Summary '!$E$11*'Loan Summary '!$E$13)>0
Name LoanPeriod: 'Loan Summary '!$E$11
Name LoanStartDate: 'Loan Summary '!$E$13
Name PaymentsPerYear: 'Loan Summary '!$E$12
Name PrintArea_SET: OFFSET('Loan Summary '!#REF!,,,'Loan Summary '!LastRow,'Loan Summary '!LastCol)
Name RowTitleRegion1..E9: 'Loan Summary '!$B$5:$D$5
Name RowTitleRegion2..I7: 'Loan Summary '!#REF!
Name RowTitleRegion3..E9: 'Loan Summary '!#REF!
Name RowTitleRegion4..H9: 'Loan Summary '!#REF!
Name ScheduledNumberOfPayments: 'Loan Summary '!#REF!
Name ScheduledPayment: 'Loan Summary '!#REF!
Name TotalEarlyPayments: SUM(#REF!)
Name TotalInterest: SUM(#REF!)

Sheet Loan Summary 
C2: Drip's Flex Line amortization schedule summary
B4: Client Terms | G4: Loan Details | Q4: Payment Schedule
B5: Approved Credit Line | E5: 100000 | G5: Loan # | H5: Loan Amount | I5: Loan Date | J5: Loan Payment Start Date | K5: Loan Payment End Date | L5: Monthly Principal Repayment | M5: Total Interest | N5: Draw Possible | O5: Remaining Limit | Q5: Payment date | R5: Beginning balance | S5: Principal Payment | T5: Interest | U5: Draw Fee | V5: Other Fees | W5: Extra Payment | X5: Delay in Payment | Y5: Overdue Interest | Z5: Actual Payment Date | AA5: Ending balance | AB5: Total Payment
B6: Annual interest rate | E6: 0.18 | G6: =IFERROR(RANK(Table4[[#This Row],[Loan Date]],Table4[[#All],[Loan Date]],1) +COUNTIF($I$6:I6,I6)-1,"") -> 1 | H6: 30000 | I6: 45315 | J6: =IF(Table4[[#This Row],[Loan Date]]<>"",IF($E$14 = "End of Month", EOMONTH(Table4[[#This Row],[Loan Date]],IF(DAY(EOMONTH(Table4[[#This Row],[Loan Date]],0)) - DAY(Table4[[#This Row],[Loan Date]])<=$E$15,1,0)),IF($E$14 = "Mid of Month", EOMONTH(Table4[[#This Row],[Loan Date]],IF(15 - DAY(Table4[[#This Row],[Loan Date]])<=$E$15,0,-1))+15,IF($E$14 = "Start of Month", EOMONTH(Table4[[#This Row],[Loan Date]],IF(DAY(EOMONTH(Table4[[#This Row],[Loan Date]],0)) - DAY(Table4[[#This Row],[Loan Date]])<=$E$15,1,0))) + 1)),"") -> 45352 | K6: =IF(Table4[[#This Row],[Loan Date]]<>"", IF($E$14 = "End of Month", EOMONTH(Table4[[#This Row],[Loan Date]],6+IF(DAY(EOMONTH(Table4[[#This Row],[Loan Date]],0)) - DAY(Table4[[#This Row],[Loan Date]])<=$E$15,0,-1)), IF($E$14 = "Mid of Month", EOMONTH(Table4[[#This Row],[Loan Date]],6+IF(15 - DAY(Table4[[#This Row],[Loan Date]])<=$E$15,-1,-2))+15, IF($E$14 = "Start of Month", EOMONTH(Table4[[#This Row],[Loan Date]],6+IF(DAY(EOMONTH(Table4[[#This Row],[Loan Date]],0)) - DAY(Table4[[#This Row],[Loan Date]])<=$E$15,0,-1)) + 1) ) ),"") -> 45505 | L6: =IF(Table4[[#This Row],[Loan Date]]<>"",Table4[[#This Row],[Loan Amount]]/PaymentsPerYear,"") -> 5000 | M6: {=IF(Table4[[#This Row],[Loan Date]]<>"", ((Table4[[#This Row],[Loan Payment Start Date]]-Table4[[#This Row],[Loan Date]])*Table4[[#This Row],[Loan Amount]]*InterestRate/360) + SUM((_xlfn.SEQUENCE(6, 1, Table4[[#This Row],[Loan Amount]]-Table4[[#This Row],[Loan Amount]]/6, -Table4[[#This Row],[Loan Amount]]/6))* (IF($E$14 = "End of Month", EOMONTH(EDATE(Table4[[#This Row],[Loan Payment Start Date]],_xlfn.SEQUENCE(6,1,1,1)),0),IF($E$14 = "Mid of Month",EDATE(Table4[[#This Row],[Loan Payment Start Date]],_xlfn.SEQUENCE(6,1,1,1)), IF($E$14 = "Start of Month", EOMONTH(EDATE(Table4[[#This Row],[Loan Payment Start Date]],_xlfn.SEQUENCE(6,1,1,1)),-1)+1))) - IF($E$14 = "End of Month", EOMONTH(EDATE(Table4[[#This Row],[Loan Payment Start Date]],_xlfn.SEQUENCE(6,1,1,1)),-1),IF($E$14 = "Mid of Month",EDATE(Table4[[#This Row],[Loan Payment Start Date]],_xlfn.SEQUENCE(6,1,0,1)), IF($E$14 = "Start of Month", EOMONTH(EDATE(Table4[[#This Row],[Loan Payment Start Date]],_xlfn.SEQUENCE(6,1,1,1)),-2)+1))))*InterestRate/360),"")} -> 1702.5 | N6: =IF(Table4[[#This Row],[Loan Amount]]<>"", IF((LoanAmount - (SUMIFS(Table4[Loan Amount],Table4[Loan Date],"<"&Table4[[#This Row],[Loan Date]]) -SUMIFS(Table5[Principal Payment],Table5[Payment date],"<="&Table4[[#This Row],[Loan Date]]) - SUMIFS(Table5[Extra Payment],Table5[Payment date],"<="&Table4[[#This Row],[Loan Date]])) > Table4[[#This Row],[Loan Amount]]),"Yes","No"),"") -> Yes | O6: =IF(Table4[[#This Row],[Loan Amount]]<>"", LoanAmount - (SUMIFS(Table4[Loan Amount],Table4[Loan Date],"<"&Table4[[#This Row],[Loan Date]]) -SUMIFS(Table5[Principal Payment],Table5[Payment date],"<="&Table4[[#This Row],[Loan Date]]) - SUMIFS(Table5[Extra Payment],Table5[Payment date],"<="&Table4[[#This Row],[Loan Date]])) - Table4[[#This Row],[Loan Amount]],"") -> 70000 | Q6: =IF($E$14="Mid of Month",(IF(EDATE(MIN(Table4[[#All],[Loan Date]]), ROW()-ROW($Q$6)) > EDATE(MAX(Table4[[#All],[Loan Payment End Date]]),1), "", (EOMONTH(EDATE(MIN(Table4[[#All],[Loan Date]]), ROW()-ROW($Q$6)),IF(DAY(EOMONTH(MIN(Table4[[#All],[Loan Date]]),0)) - DAY(MIN(Table4[[#All],[Loan Date]])) <= $E$15, 0, -1))+ 15))), IF($E$14="End of Month",(IF(EDATE(MIN(Table4[[#All],[Loan Date]]), ROW()-ROW($Q$6)) > MAX(Table4[[#All],[Loan Payment End Date]]), "", (EOMONTH(EDATE(MIN(Table4[[#All],[Loan Date]]), ROW()-ROW($Q$6)),IF(31 - DAY(MIN(Table4[[#All],[Loan Date]])) <= $E$15, 1, 0))))), IF($E$14="Start of Month",(IF(EDATE(MIN(Table4[[#All],[Loan Date]]), ROW()-ROW($Q$6)) > MAX(Table4[[#All],[Loan Payment End Date]]), "", (EOMONTH(EDATE(MIN(Table4[[#All],[Loan Date]]), ROW()-ROW($Q$6)),IF(31 - DAY(MIN(Table4[[#All],[Loan Date]])) <= $E$15, 1, 0))) + 1 ))) ) ) -> 45352 | R6: =IF(Table5[[#This Row],[Payment date]]<>"", SUMIFS(Table4[[#All],[Loan Amount]],Table4[[#All],[Loan Date]],"<="&Table5[[#This Row],[Payment date]]) - SUM($S$5:S5)- SUM($W$5:W5),"") -> 50000 | S6: =IF(Table5[[#This Row],[Payment date]]<>"",SUM('Individual Loan Schedule'!C9:HR9) - SUM('Early Payments'!D9:HS9),"") -> 5000 | T6: {=IF(Table5[[#This Row],[Payment date]]<>"",((SUMIFS(Table4[Loan Amount],Table4[Loan Payment Start Date],"<"&Table5[[#This Row],[Payment date]]) - SUM($S$5:$S5) - SUM($W$5:W5))*InterestRate*(Table5[[#This Row],[Payment date]] - IF($E$14="End of Month",EOMONTH(Table5[[#This Row],[Payment date]],-1), IF($E$14="Mid of Month",EOMONTH(Table5[[#This Row],[Payment date]],-2)+15, IF($E$14="Start of Month",EOMONTH(Table5[[#This Row],[Payment date]],-2) + 1))) )/360) + (SUM(IFERROR((IF(Table4[Loan Payment Start Date]=Table5[[#This Row],[Payment date]],Table4[Loan Amount],"")*(Table4[Loan Payment Start Date]-Table4[Loan Date])*InterestRate/360),0),0)),"")} -> 555 | U6: =IF(Table5[[#This Row],[Payment date]]<>"",SUMIFS(Table4[[#All],[Loan Amount]],Table4[[#All],[Loan Payment Start Date]],"="&Table5[[#This Row],[Payment date]])*($E$7),"") -> 90 | V6: {=IF(Table5[[#This Row],[Payment date]]<>"",IF(Table5[[#This Row],[Payment date]]=MIN(Table4[[#All],[Loan Payment Start Date]]),$E$8+$E$10*LoanAmount,0) + IF(Table5[[#This Row],[Payment date]] =MIN(_xlfn._xlws.FILTER(Table5[Payment date],(Table5[Payment date]>=EDATE(LoanStartDate,12*DATEDIF(LoanStartDate,Table5[[#This Row],[Payment date]],"y")))*(Table5[Beginning balance]<>0))), $E$9*LoanAmount,0),"")} -> 849 | X6: 10 | Y6: =IF(Table5[[#This Row],[Payment date]]<>"",(SUMIFS(Table4[Loan Amount],Table4[Loan Payment Start Date],"<="&Table5[[#This Row],[Payment date]]) - SUM($S$5:$S5) - - SUM($W$5:W5))*Table5[[#This Row],[Delay in Payment ]]*($E$16+ InterestRate)/365,"") -> 443.83562 | Z6: =IF(Table5[[#This Row],[Payment date]]<>"",Table5[[#This Row],[Payment date]]+Table5[[#This Row],[Delay in Payment ]],"") -> 45362 | AA6: =IF(Table5[[#This Row],[Payment date]]<>"",Table5[[#This Row],[Beginning balance]]-Table5[[#This Row],[Principal Payment]] - Table5[[#This Row],[Extra Payment]],"") -> 45000 | AB6: =IF(Table5[[#This Row],[Payment date]]<>"",Table5[[#This Row],[Draw Fee]]+Table5[[#This Row],[Interest]]+Table5[[#This Row],[Principal Payment]]+Table5[[#This Row],[Overdue Interest]],"") -> 6088.8356
B7: Transaction Fee | E7: 0.003 | G7: =IFERROR(RANK(Table4[[#This Row],[Loan Date]],Table4[[#All],[Loan Date]],1) +COUNTIF($I$6:I7,I7)-1,"") -> 2 | H7: 20000 | I7: 45345 | J7: =IF(Table4[[#This Row],[Loan Date]]<>"",IF($E$14 = "End of Month", EOMONTH(Table4[[#This Row],[Loan Date]],IF(DAY(EOMONTH(Table4[[#This Row],[Loan Date]],0)) - DAY(Table4[[#This Row],[Loan Date]])<=$E$15,1,0)),IF($E$14 = "Mid of Month", EOMONTH(Table4[[#This Row],[Loan Date]],IF(15 - DAY(Table4[[#This Row],[Loan Date]])<=$E$15,0,-1))+15,IF($E$14 = "Start of Month", EOMONTH(Table4[[#This Row],[Loan Date]],IF(DAY(EOMONTH(Table4[[#This Row],[Loan Date]],0)) - DAY(Table4[[#This Row],[Loan Date]])<=$E$15,1,0))) + 1)),"") -> 45383 | K7: =IF(Table4[[#This Row],[Loan Date]]<>"", IF($E$14 = "End of Month", EOMONTH(Table4[[#This Row],[Loan Date]],6+IF(DAY(EOMONTH(Table4[[#This Row],[Loan Date]],0)) - DAY(Table4[[#This Row],[Loan Date]])<=$E$15,0,-1)), IF($E$14 = "Mid of Month", EOMONTH(Table4[[#This Row],[Loan Date]],6+IF(15 - DAY(Table4[[#This Row],[Loan Date]])<=$E$15,-1,-2))+15, IF($E$14 = "Start of Month", EOMONTH(Table4[[#This Row],[Loan Date]],6+IF(DAY(EOMONTH(Table4[[#This Row],[Loan Date]],0)) - DAY(Table4[[#This Row],[Loan Date]])<=$E$15,0,-1)) + 1) ) ),"") -> 45536 | L7: =IF(Table4[[#This Row],[Loan Date]]<>"",Table4[[#This Row],[Loan Amount]]/PaymentsPerYear,"") -> 3333.3333 | M7: {=IF(Table4[[#This Row],[Loan Date]]<>"", ((Table4[[#This Row],[Loan Payment Start Date]]-Table4[[#This Row],[Loan Date]])*Table4[[#This Row],[Loan Amount]]*InterestRate/360) + SUM((_xlfn.SEQUENCE(6, 1, Table4[[#This Row],[Loan Amount]]-Table4[[#This Row],[Loan Amount]]/6, -Table4[[#This Row],[Loan Amount]]/6))* (IF($E$14 = "End of Month", EOMONTH(EDATE(Table4[[#This Row],[Loan Payment Start Date]],_xlfn.SEQUENCE(6,1,1,1)),0),IF($E$14 = "Mid of Month",EDATE(Table4[[#This Row],[Loan Payment Start Date]],_xlfn.SEQUENCE(6,1,1,1)), IF($E$14 = "Start of Month", EOMONTH(EDATE(Table4[[#This Row],[Loan Payment Start Date]],_xlfn.SEQUENCE(6,1,1,1)),-1)+1))) - IF($E$14 = "End of Month", EOMONTH(EDATE(Table4[[#This Row],[Loan Payment Start Date]],_xlfn.SEQUENCE(6,1,1,1)),-1),IF($E$14 = "Mid of Month",EDATE(Table4[[#This Row],[Loan Payment Start Date]],_xlfn.SEQUENCE(6,1,0,1)), IF($E$14 = "Start of Month", EOMONTH(EDATE(Table4[[#This Row],[Loan Payment Start Date]],_xlfn.SEQUENCE(6,1,1,1)),-2)+1))))*InterestRate/360),"")} -> 1141.6667 | N7: =IF(Table4[[#This Row],[Loan Amount]]<>"", IF((LoanAmount - (SUMIFS(Table4[Loan Amount],Table4[Loan Date],"<"&Table4[[#This Row],[Loan Date]]) -SUMIFS(Table5[Principal Payment],Table5[Payment date],"<="&Table4[[#This Row],[Loan Date]]) - SUMIFS(Table5[Extra Payment],Table5[Payment date],"<="&Table4[[#This Row],[Loan Date]])) > Table4[[#This Row],[Loan Amount]]),"Yes","No"),"") -> Yes | O7: =IF(Table4[[#This Row],[Loan Amount]]<>"", LoanAmount - (SUMIFS(Table4[Loan Amount],Table4[Loan Date],"<"&Table4[[#This Row],[Loan Date]]) -SUMIFS(Table5[Principal Payment],Table5[Payment date],"<="&Table4[[#This Row],[Loan Date]]) - SUMIFS(Table5[Extra Payment],Table5[Payment date],"<="&Table4[[#This Row],[Loan Date]])) - Table4[[#This Row],[Loan Amount]],"") -> 50000 | Q7: =IF($E$14="Mid of Month",(IF(EDATE(MIN(Table4[[#All],[Loan Date]]), ROW()-ROW($Q$6)) > EDATE(MAX(Table4[[#All],[Loan Payment End Date]]),1), "", (EOMONTH(EDATE(MIN(Table4[[#All],[Loan Date]]), ROW()-ROW($Q$6)),IF(DAY(EOMONTH(MIN(Table4[[#All],[Loan Date]]),0)) - DAY(MIN(Table4[[#All],[Loan Date]])) <= $E$15, 0, -1))+ 15))), IF($E$14="End of Month",(IF(EDATE(MIN(Table4[[#All],[Loan Date]]), ROW()-ROW($Q$6)) > MAX(Table4[[#All],[Loan Payment End Date]]), "", (EOMONTH(EDATE(MIN(Table4[[#All],[Loan Date]]), ROW()-ROW($Q$6)),IF(31 - DAY(MIN(Table4[[#All],[Loan Date]])) <= $E$15, 1, 0))))), IF($E$14="Start of Month",(IF(EDATE(MIN(Table4[[#All],[Loan Date]]), ROW()-ROW($Q$6)) > MAX(Table4[[#All],[Loan Payment End Date]]), "", (EOMONTH(EDATE(MIN(Table4[[#All],[Loan Date]]), ROW()-ROW($Q$6)),IF(31 - DAY(MIN(Table4[[#All],[Loan Date]])) <= $E$15, 1, 0))) + 1 ))) ) ) -> 45383 | R7: =IF(Table5[[#This Row],[Payment date]]<>"", SUMIFS(Table4[[#All],[Loan Amount]],Table4[[#All],[Loan Date]],"<="&Table5[[#This Row],[Payment date]]) - SUM($S$5:S6)- SUM($W$5:W6),"") -> 45000 | S7: =IF(Table5[[#This Row],[Payment date]]<>"",SUM('Individual Loan Schedule'!C10:HR10) - SUM('Early Payments'!D10:HS10),"") -> 8333.3333 | T7: {=IF(Table5[[#This Row],[Payment date]]<>"",((SUMIFS(Table4[Loan Amount],Table4[Loan Payment Start Date],"<"&Table5[[#This Row],[Payment date]]) - SUM($S$5:$S6) - SUM($W$5:W6))*InterestRate*(Table5[[#This Row],[Payment date]] - IF($E$14="End of Month",EOMONTH(Table5[[#This Row],[Payment date]],-1), IF($E$14="Mid of Month",EOMONTH(Table5[[#This Row],[Payment date]],-2)+15, IF($E$14="Start of Month",EOMONTH(Table5[[#This Row],[Payment date]],-2) + 1))) )/360) + (SUM(IFERROR((IF(Table4[Loan Payment Start Date]=Table5[[#This Row],[Payment date]],Table4[Loan Amount],"")*(Table4[Loan Payment Start Date]-Table4[Loan Date])*InterestRate/360),0),0)),"")} -> 767.5 | U7: =IF(Table5[[#This Row],[Payment date]]<>"",SUMIFS(Table4[[#All],[Loan Amount]],Table4[[#All],[Loan Payment Start Date]],"="&Table5[[#This Row],[Payment date]])*($E$7),"") -> 60 | V7: {=IF(Table5[[#This Row],[Payment date]]<>"",IF(Table5[[#This Row],[Payment date]]=MIN(Table4[[#All],[Loan Payment Start Date]]),$E$8+$E$10*LoanAmount,0) + IF(Table5[[#This Row],[Payment date]] =MIN(_xlfn._xlws.FILTER(Table5[Payment date],(Table5[Payment date]>=EDATE(LoanStartDate,12*DATEDIF(LoanStartDate,Table5[[#This Row],[Payment date]],"y")))*(Table5[Beginning balance]<>0))), $E$9*LoanAmount,0),"")} -> 0 | Y7: =IF(Table5[[#This Row],[Payment date]]<>"",(SUMIFS(Table4[Loan Amount],Table4[Loan Payment Start Date],"<="&Table5[[#This Row],[Payment date]]) - SUM($S$5:$S6) - - SUM($W$5:W6))*Table5[[#This Row],[Delay in Payment ]]*($E$16+ InterestRate)/365,"") -> 0 | Z7: =IF(Table5[[#This Row],[Payment date]]<>"",Table5[[#This Row],[Payment date]]+Table5[[#This Row],[Delay in Payment ]],"") -> 45383 | AA7: =IF(Table5[[#This Row],[Payment date]]<>"",Table5[[#This Row],[Beginning balance]]-Table5[[#This Row],[Principal Payment]] - Table5[[#This Row],[Extra Payment]],"") -> 36666.667 | AB7: =IF(Table5[[#This Row],[Payment date]]<>"",Table5[[#This Row],[Draw Fee]]+Table5[[#This Row],[Interest]]+Table5[[#This Row],[Principal Payment]]+Table5[[#This Row],[Overdue Interest]],"") -> 9160.8333
B8: Credit Evaluation Fee | E8: 99 | G8: =IFERROR(RANK(Table4[[#This Row],[Loan Date]],Table4[[#All],[Loan Date]],1) +COUNTIF($I$6:I8,I8)-1,"") -> 3 | H8: 50000 | I8: 45403 | J8: =IF(Table4[[#This Row],[Loan Date]]<>"",IF($E$14 = "End of Month", EOMONTH(Table4[[#This Row],[Loan Date]],IF(DAY(EOMONTH(Table4[[#This Row],[Loan Date]],0)) - DAY(Table4[[#This Row],[Loan Date]])<=$E$15,1,0)),IF($E$14 = "Mid of Month", EOMONTH(Table4[[#This Row],[Loan Date]],IF(15 - DAY(Table4[[#This Row],[Loan Date]])<=$E$15,0,-1))+15,IF($E$14 = "Start of Month", EOMONTH(Table4[[#This Row],[Loan Date]],IF(DAY(EOMONTH(Table4[[#This Row],[Loan Date]],0)) - DAY(Table4[[#This Row],[Loan Date]])<=$E$15,1,0))) + 1)),"") -> 45413 | K8: =IF(Table4[[#This Row],[Loan Date]]<>"", IF($E$14 = "End of Month", EOMONTH(Table4[[#This Row],[Loan Date]],6+IF(DAY(EOMONTH(Table4[[#This Row],[Loan Date]],0)) - DAY(Table4[[#This Row],[Loan Date]])<=$E$15,0,-1)), IF($E$14 = "Mid of Month", EOMONTH(Table4[[#This Row],[Loan Date]],6+IF(15 - DAY(Table4[[#This Row],[Loan Date]])<=$E$15,-1,-2))+15, IF($E$14 = "Start of Month", EOMONTH(Table4[[#This Row],[Loan Date]],6+IF(DAY(EOMONTH(Table4[[#This Row],[Loan Date]],0)) - DAY(Table4[[#This Row],[Loan Date]])<=$E$15,0,-1)) + 1) ) ),"") -> 45566 | L8: =IF(Table4[[#This Row],[Loan Date]]<>"",Table4[[#This Row],[Loan Amount]]/PaymentsPerYear,"") -> 8333.3333 | M8: {=IF(Table4[[#This Row],[Loan Date]]<>"", ((Table4[[#This Row],[Loan Payment Start Date]]-Table4[[#This Row],[Loan Date]])*Table4[[#This Row],[Loan Amount]]*InterestRate/360) + SUM((_xlfn.SEQUENCE(6, 1, Table4[[#This Row],[Loan Amount]]-Table4[[#This Row],[Loan Amount]]/6, -Table4[[#This Row],[Loan Amount]]/6))* (IF($E$14 = "End of Month", EOMONTH(EDATE(Table4[[#This Row],[Loan Payment Start Date]],_xlfn.SEQUENCE(6,1,1,1)),0),IF($E$14 = "Mid of Month",EDATE(Table4[[#This Row],[Loan Payment Start Date]],_xlfn.SEQUENCE(6,1,1,1)), IF($E$14 = "Start of Month", EOMONTH(EDATE(Table4[[#This Row],[Loan Payment Start Date]],_xlfn.SEQUENCE(6,1,1,1)),-1)+1))) - IF($E$14 = "End of Month", EOMONTH(EDATE(Table4[[#This Row],[Loan Payment Start Date]],_xlfn.SEQUENCE(6,1,1,1)),-1),IF($E$14 = "Mid of Month",EDATE(Table4[[#This Row],[Loan Payment Start Date]],_xlfn.SEQUENCE(6,1,0,1)), IF($E$14 = "Start of Month", EOMONTH(EDATE(Table4[[#This Row],[Loan Payment Start Date]],_xlfn.SEQUENCE(6,1,1,1)),-2)+1))))*InterestRate/360),"")} -> 2166.6667 | N8: =IF(Table4[[#This Row],[Loan Amount]]<>"", IF((LoanAmount - (SUMIFS(Table4[Loan Amount],Table4[Loan Date],"<"&Table4[[#This Row],[Loan Date]]) -SUMIFS(Table5[Principal Payment],Table5[Payment date],"<="&Table4[[#This Row],[Loan Date]]) - SUMIFS(Table5[Extra Payment],Table5[Payment date],"<="&Table4[[#This Row],[Loan Date]])) > Table4[[#This Row],[Loan Amount]]),"Yes","No"),"") -> Yes | O8: =IF(Table4[[#This Row],[Loan Amount]]<>"", LoanAmount - (SUMIFS(Table4[Loan Amount],Table4[Loan Date],"<"&Table4[[#This Row],[Loan Date]]) -SUMIFS(Table5[Principal Payment],Table5[Payment date],"<="&Table4[[#This Row],[Loan Date]]) - SUMIFS(Table5[Extra Payment],Table5[Payment date],"<="&Table4[[#This Row],[Loan Date]])) - Table4[[#This Row],[Loan Amount]],"") -> 13333.333 | Q8: =IF($E$14="Mid of Month",(IF(EDATE(MIN(Table4[[#All],[Loan Date]]), ROW()-ROW($Q$6)) > EDATE(MAX(Table4[[#All],[Loan Payment End Date]]),1), "", (EOMONTH(EDATE(MIN(Table4[[#All],[Loan Date]]), ROW()-ROW($Q$6)),IF(DAY(EOMONTH(MIN(Table4[[#All],[Loan Date]]),0)) - DAY(MIN(Table4[[#All],[Loan Date]])) <= $E$15, 0, -1))+ 15))), IF($E$14="End of Month",(IF(EDATE(MIN(Table4[[#All],[Loan Date]]), ROW()-ROW($Q$6)) > MAX(Table4[[#All],[Loan Payment End Date]]), "", (EOMONTH(EDATE(MIN(Table4[[#All],[Loan Date]]), ROW()-ROW($Q$6)),IF(31 - DAY(MIN(Table4[[#All],[Loan Date]])) <= $E$15, 1, 0))))), IF($E$14="Start of Month",(IF(EDATE(MIN(Table4[[#All],[Loan Date]]), ROW()-ROW($Q$6)) > MAX(Table4[[#All],[Loan Payment End Date]]), "", (EOMONTH(EDATE(MIN(Table4[[#All],[Loan Date]]), ROW()-ROW($Q$6)),IF(31 - DAY(MIN(Table4[[#All],[Loan Date]])) <= $E$15, 1, 0))) + 1 ))) ) ) -> 45413 | R8: =IF(Table5[[#This Row],[Payment date]]<>"", SUMIFS(Table4[[#All],[Loan Amount]],Table4[[#All],[Loan Date]],"<="&Table5[[#This Row],[Payment date]]) - SUM($S$5:S7)- SUM($W$5:W7),"") -> 86666.667 | S8: =IF(Table5[[#This Row],[Payment date]]<>"",SUM('Individual Loan Schedule'!C11:HR11) - SUM('Early Payments'!D11:HS11),"") -> 16666.667 | T8: {=IF(Table5[[#This Row],[Payment date]]<>"",((SUMIFS(Table4[Loan Amount],Table4[Loan Payment Start Date],"<"&Table5[[#This Row],[Payment date]]) - SUM($S$5:$S7) - SUM($W$5:W7))*InterestRate*(Table5[[#This Row],[Payment date]] - IF($E$14="End of Month",EOMONTH(Table5[[#This Row],[Payment date]],-1), IF($E$14="Mid of Month",EOMONTH(Table5[[#This Row],[Payment date]],-2)+15, IF($E$14="Start of Month",EOMONTH(Table5[[#This Row],[Payment date]],-2) + 1))) )/360) + (SUM(IFERROR((IF(Table4[Loan Payment Start Date]=Table5[[#This Row],[Payment date]],Table4[Loan Amount],"")*(Table4[Loan Payment Start Date]-Table4[Loan Date])*InterestRate/360),0),0)),"")} -> 800 | U8: =IF(Table5[[#This Row],[Payment date]]<>"",SUMIFS(Table4[[#All],[Loan Amount]],Table4[[#All],[Loan Payment Start Date]],"="&Table5[[#This Row],[Payment date]])*($E$7),"") -> 150 | V8: {=IF(Table5[[#This Row],[Payment date]]<>"",IF(Table5[[#This Row],[Payment date]]=MIN(Table4[[#All],[Loan Payment Start Date]]),$E$8+$E$10*LoanAmount,0) + IF(Table5[[#This Row],[Payment date]] =MIN(_xlfn._xlws.FILTER(Table5[Payment date],(Table5[Payment date]>=EDATE(LoanStartDate,12*DATEDIF(LoanStartDate,Table5[[#This Row],[Payment date]],"y")))*(Table5[Beginning balance]<>0))), $E$9*LoanAmount,0),"")} -> 0 | W8: 17000 | Y8: =IF(Table5[[#This Row],[Payment date]]<>"",(SUMIFS(Table4[Loan Amount],Table4[Loan Payment Start Date],"<="&Table5[[#This Row],[Payment date]]) - SUM($S$5:$S7) - - SUM($W$5:W7))*Table5[[#This Row],[Delay in Payment ]]*($E$16+ InterestRate)/365,"") -> 0 | Z8: =IF(Table5[[#This Row],[Payment date]]<>"",Table5[[#This Row],[Payment date]]+Table5[[#This Row],[Delay in Payment ]],"") -> 45413 | AA8: =IF(Table5[[#This Row],[Payment date]]<>"",Table5[[#This Row],[Beginning balance]]-Table5[[#This Row],[Principal Payment]] - Table5[[#This Row],[Extra Payment]],"") -> 53000 | AB8: =IF(Table5[[#This Row],[Payment date]]<>"",Table5[[#This Row],[Draw Fee]]+Table5[[#This Row],[Interest]]+Table5[[#This Row],[Principal Payment]]+Table5[[#This Row],[Overdue Interest]],"") -> 17616.667
B9: Annual Fee (of the approved credit line) | E9: 0.005 | G9: =IFERROR(RANK(Table4[[#This Row],[Loan Date]],Table4[[#All],[Loan Date]],1) +COUNTIF($I$6:I9,I9)-1,"") -> 4 | H9: 15000 | I9: 45613 | J9: =IF(Table4[[#This Row],[Loan Date]]<>"",IF($E$14 = "End of Month", EOMONTH(Table4[[#This Row],[Loan Date]],IF(DAY(EOMONTH(Table4[[#This Row],[Loan Date]],0)) - DAY(Table4[[#This Row],[Loan Date]])<=$E$15,1,0)),IF($E$14 = "Mid of Month", EOMONTH(Table4[[#This Row],[Loan Date]],IF(15 - DAY(Table4[[#This Row],[Loan Date]])<=$E$15,0,-1))+15,IF($E$14 = "Start of Month", EOMONTH(Table4[[#This Row],[Loan Date]],IF(DAY(EOMONTH(Table4[[#This Row],[Loan Date]],0)) - DAY(Table4[[#This Row],[Loan Date]])<=$E$15,1,0))) + 1)),"") -> 45627 | K9: =IF(Table4[[#This Row],[Loan Date]]<>"", IF($E$14 = "End of Month", EOMONTH(Table4[[#This Row],[Loan Date]],6+IF(DAY(EOMONTH(Table4[[#This Row],[Loan Date]],0)) - DAY(Table4[[#This Row],[Loan Date]])<=$E$15,0,-1)), IF($E$14 = "Mid of Month", EOMONTH(Table4[[#This Row],[Loan Date]],6+IF(15 - DAY(Table4[[#This Row],[Loan Date]])<=$E$15,-1,-2))+15, IF($E$14 = "Start of Month", EOMONTH(Table4[[#This Row],[Loan Date]],6+IF(DAY(EOMONTH(Table4[[#This Row],[Loan Date]],0)) - DAY(Table4[[#This Row],[Loan Date]])<=$E$15,0,-1)) + 1) ) ),"") -> 45778 | L9: =IF(Table4[[#This Row],[Loan Date]]<>"",Table4[[#This Row],[Loan Amount]]/PaymentsPerYear,"") -> 2500 | M9: {=IF(Table4[[#This Row],[Loan Date]]<>"", ((Table4[[#This Row],[Loan Payment Start Date]]-Table4[[#This Row],[Loan Date]])*Table4[[#This Row],[Loan Amount]]*InterestRate/360) + SUM((_xlfn.SEQUENCE(6, 1, Table4[[#This Row],[Loan Amount]]-Table4[[#This Row],[Loan Amount]]/6, -Table4[[#This Row],[Loan Amount]]/6))* (IF($E$14 = "End of Month", EOMONTH(EDATE(Table4[[#This Row],[Loan Payment Start Date]],_xlfn.SEQUENCE(6,1,1,1)),0),IF($E$14 = "Mid of Month",EDATE(Table4[[#This Row],[Loan Payment Start Date]],_xlfn.SEQUENCE(6,1,1,1)), IF($E$14 = "Start of Month", EOMONTH(EDATE(Table4[[#This Row],[Loan Payment Start Date]],_xlfn.SEQUENCE(6,1,1,1)),-1)+1))) - IF($E$14 = "End of Month", EOMONTH(EDATE(Table4[[#This Row],[Loan Payment Start Date]],_xlfn.SEQUENCE(6,1,1,1)),-1),IF($E$14 = "Mid of Month",EDATE(Table4[[#This Row],[Loan Payment Start Date]],_xlfn.SEQUENCE(6,1,0,1)), IF($E$14 = "Start of Month", EOMONTH(EDATE(Table4[[#This Row],[Loan Payment Start Date]],_xlfn.SEQUENCE(6,1,1,1)),-2)+1))))*InterestRate/360),"")} -> 673.75 | N9: =IF(Table4[[#This Row],[Loan Amount]]<>"", IF((LoanAmount - (SUMIFS(Table4[Loan Amount],Table4[Loan Date],"<"&Table4[[#This Row],[Loan Date]]) -SUMIFS(Table5[Principal Payment],Table5[Payment date],"<="&Table4[[#This Row],[Loan Date]]) - SUMIFS(Table5[Extra Payment],Table5[Payment date],"<="&Table4[[#This Row],[Loan Date]])) > Table4[[#This Row],[Loan Amount]]),"Yes","No"),"") -> Yes | O9: =IF(Table4[[#This Row],[Loan Amount]]<>"", LoanAmount - (SUMIFS(Table4[Loan Amount],Table4[Loan Date],"<"&Table4[[#This Row],[Loan Date]]) -SUMIFS(Table5[Principal Payment],Table5[Payment date],"<="&Table4[[#This Row],[Loan Date]]) - SUMIFS(Table5[Extra Payment],Table5[Payment date],"<="&Table4[[#This Row],[Loan Date]])) - Table4[[#This Row],[Loan Amount]],"") -> 85000 | Q9: =IF($E$14="Mid of Month",(IF(EDATE(MIN(Table4[[#All],[Loan Date]]), ROW()-ROW($Q$6)) > EDATE(MAX(Table4[[#All],[Loan Payment End Date]]),1), "", (EOMONTH(EDATE(MIN(Table4[[#All],[Loan Date]]), ROW()-ROW($Q$6)),IF(DAY(EOMONTH(MIN(Table4[[#All],[Loan Date]]),0)) - DAY(MIN(Table4[[#All],[Loan Date]])) <= $E$15, 0, -1))+ 15))), IF($E$14="End of Month",(IF(EDATE(MIN(Table4[[#All],[Loan Date]]), ROW()-ROW($Q$6)) > MAX(Table4[[#All],[Loan Payment End Date]]), "", (EOMONTH(EDATE(MIN(Table4[[#All],[Loan Date]]), ROW()-ROW($Q$6)),IF(31 - DAY(MIN(Table4[[#All],[Loan Date]])) <= $E$15, 1, 0))))), IF($E$14="Start of Month",(IF(EDATE(MIN(Table4[[#All],[Loan Date]]), ROW()-ROW($Q$6)) > MAX(Table4[[#All],[Loan Payment End Date]]), "", (EOMONTH(EDATE(MIN(Table4[[#All],[Loan Date]]), ROW()-ROW($Q$6)),IF(31 - DAY(MIN(Table4[[#All],[Loan Date]])) <= $E$15, 1, 0))) + 1 ))) ) ) -> 45444 | R9: =IF(Table5[[#This Row],[Payment date]]<>"", SUMIFS(Table4[[#All],[Loan Amount]],Table4[[#All],[Loan Date]],"<="&Table5[[#This Row],[Payment date]]) - SUM($S$5:S8)- SUM($W$5:W8),"") -> 53000 | S9: =IF(Table5[[#This Row],[Payment date]]<>"",SUM('Individual Loan Schedule'!C12:HR12) - SUM('Early Payments'!D12:HS12),"") -> 11666.667 | T9: {=IF(Table5[[#This Row],[Payment date]]<>"",((SUMIFS(Table4[Loan Amount],Table4[Loan Payment Start Date],"<"&Table5[[#This Row],[Payment date]]) - SUM($S$5:$S8) - SUM($W$5:W8))*InterestRate*(Table5[[#This Row],[Payment date]] - IF($E$14="End of Month",EOMONTH(Table5[[#This Row],[Payment date]],-1), IF($E$14="Mid of Month",EOMONTH(Table5[[#This Row],[Payment date]],-2)+15, IF($E$14="Start of Month",EOMONTH(Table5[[#This Row],[Payment date]],-2) + 1))) )/360) + (SUM(IFERROR((IF(Table4[Loan Payment Start Date]=Table5[[#This Row],[Payment date]],Table4[Loan Amount],"")*(Table4[Loan Payment Start Date]-Table4[Loan Date])*InterestRate/360),0),0)),"")} -> 821.5 | U9: =IF(Table5[[#This Row],[Payment date]]<>"",SUMIFS(Table4[[#All],[Loan Amount]],Table4[[#All],[Loan Payment Start Date]],"="&Table5[[#This Row],[Payment date]])*($E$7),"") -> 0 | V9: {=IF(Table5[[#This Row],[Payment date]]<>"",IF(Table5[[#This Row],[Payment date]]=MIN(Table4[[#All],[Loan Payment Start Date]]),$E$8+$E$10*LoanAmount,0) + IF(Table5[[#This Row],[Payment date]] =MIN(_xlfn._xlws.FILTER(Table5[Payment date],(Table5[Payment date]>=EDATE(LoanStartDate,12*DATEDIF(LoanStartDate,Table5[[#This Row],[Payment date]],"y")))*(Table5[Beginning balance]<>0))), $E$9*LoanAmount,0),"")} -> 0 | Y9: =IF(Table5[[#This Row],[Payment date]]<>"",(SUMIFS(Table4[Loan Amount],Table4[Loan Payment Start Date],"<="&Table5[[#This Row],[Payment date]]) - SUM($S$5:$S8) - - SUM($W$5:W8))*Table5[[#This Row],[Delay in Payment ]]*($E$16+ InterestRate)/365,"") -> 0 | Z9: =IF(Table5[[#This Row],[Payment date]]<>"",Table5[[#This Row],[Payment date]]+Table5[[#This Row],[Delay in Payment ]],"") -> 45444 | AA9: =IF(Table5[[#This Row],[Payment date]]<>"",Table5[[#This Row],[Beginning balance]]-Table5[[#This Row],[Principal Payment]] - Table5[[#This Row],[Extra Payment]],"") -> 41333.333 | AB9: =IF(Table5[[#This Row],[Payment date]]<>"",Table5[[#This Row],[Draw Fee]]+Table5[[#This Row],[Interest]]+Table5[[#This Row],[Principal Payment]]+Table5[[#This Row],[Overdue Interest]],"") -> 12488.167
B10: Onboarding Fee (of the approved credit line) | E10: 0.0025 | G10: =IFERROR(RANK(Table4[[#This Row],[Loan Date]],Table4[[#All],[Loan Date]],1) +COUNTIF($I$6:I10,I10)-1,"") | J10: =IF(Table4[[#This Row],[Loan Date]]<>"",IF($E$14 = "End of Month", EOMONTH(Table4[[#This Row],[Loan Date]],IF(DAY(EOMONTH(Table4[[#This Row],[Loan Date]],0)) - DAY(Table4[[#This Row],[Loan Date]])<=$E$15,1,0)),IF($E$14 = "Mid of Month", EOMONTH(Table4[[#This Row],[Loan Date]],IF(15 - DAY(Table4[[#This Row],[Loan Date]])<=$E$15,0,-1))+15,IF($E$14 = "Start of Month", EOMONTH(Table4[[#This Row],[Loan Date]],IF(DAY(EOMONTH(Table4[[#This Row],[Loan Date]],0)) - DAY(Table4[[#This Row],[Loan Date]])<=$E$15,1,0))) + 1)),"") | K10: =IF(Table4[[#This Row],[Loan Date]]<>"", IF($E$14 = "End of Month", EOMONTH(Table4[[#This Row],[Loan Date]],6+IF(DAY(EOMONTH(Table4[[#This Row],[Loan Date]],0)) - DAY(Table4[[#This Row],[Loan Date]])<=$E$15,0,-1)), IF($E$14 = "Mid of Month", EOMONTH(Table4[[#This Row],[Loan Date]],6+IF(15 - DAY(Table4[[#This Row],[Loan Date]])<=$E$15,-1,-2))+15, IF($E$14 = "Start of Month", EOMONTH(Table4[[#This Row],[Loan Date]],6+IF(DAY(EOMONTH(Table4[[#This Row],[Loan Date]],0)) - DAY(Table4[[#This Row],[Loan Date]])<=$E$15,0,-1)) + 1) ) ),"") | L10: =IF(Table4[[#This Row],[Loan Date]]<>"",Table4[[#This Row],[Loan Amount]]/PaymentsPerYear,"") | M10: {=IF(Table4[[#This Row],[Loan Date]]<>"", ((Table4[[#This Row],[Loan Payment Start Date]]-Table4[[#This Row],[Loan Date]])*Table4[[#This Row],[Loan Amount]]*InterestRate/360) + SUM((_xlfn.SEQUENCE(6, 1, Table4[[#This Row],[Loan Amount]]-Table4[[#This Row],[Loan Amount]]/6, -Table4[[#This Row],[Loan Amount]]/6))* (IF($E$14 = "End of Month", EOMONTH(EDATE(Table4[[#This Row],[Loan Payment Start Date]],_xlfn.SEQUENCE(6,1,1,1)),0),IF($E$14 = "Mid of Month",EDATE(Table4[[#This Row],[Loan Payment Start Date]],_xlfn.SEQUENCE(6,1,1,1)), IF($E$14 = "Start of Month", EOMONTH(EDATE(Table4[[#This Row],[Loan Payment Start Date]],_xlfn.SEQUENCE(6,1,1,1)),-1)+1))) - IF($E$14 = "End of Month", EOMONTH(EDATE(Table4[[#This Row],[Loan Payment Start Date]],_xlfn.SEQUENCE(6,1,1,1)),-1),IF($E$14 = "Mid of Month",EDATE(Table4[[#This Row],[Loan Payment Start Date]],_xlfn.SEQUENCE(6,1,0,1)), IF($E$14 = "Start of Month", EOMONTH(EDATE(Table4[[#This Row],[Loan Payment Start Date]],_xlfn.SEQUENCE(6,1,1,1)),-2)+1))))*InterestRate/360),"")} | N10: =IF(Table4[[#This Row],[Loan Amount]]<>"", IF((LoanAmount - (SUMIFS(Table4[Loan Amount],Table4[Loan Date],"<"&Table4[[#This Row],[Loan Date]]) -SUMIFS(Table5[Principal Payment],Table5[Payment date],"<="&Table4[[#This Row],[Loan Date]]) - SUMIFS(Table5[Extra Payment],Table5[Payment date],"<="&Table4[[#This Row],[Loan Date]])) > Table4[[#This Row],[Loan Amount]]),"Yes","No"),"") | O10: =IF(Table4[[#This Row],[Loan Amount]]<>"", LoanAmount - (SUMIFS(Table4[Loan Amount],Table4[Loan Date],"<"&Table4[[#This Row],[Loan Date]]) -SUMIFS(Table5[Principal Payment],Table5[Payment date],"<="&Table4[[#This Row],[Loan Date]]) - SUMIFS(Table5[Extra Payment],Table5[Payment date],"<="&Table4[[#This Row],[Loan Date]])) - Table4[[#This Row],[Loan Amount]],"") | Q10: =IF($E$14="Mid of Month",(IF(EDATE(MIN(Table4[[#All],[Loan Date]]), ROW()-ROW($Q$6)) > EDATE(MAX(Table4[[#All],[Loan Payment End Date]]),1), "", (EOMONTH(EDATE(MIN(Table4[[#All],[Loan Date]]), ROW()-ROW($Q$6)),IF(DAY(EOMONTH(MIN(Table4[[#All],[Loan Date]]),0)) - DAY(MIN(Table4[[#All],[Loan Date]])) <= $E$15, 0, -1))+ 15))), IF($E$14="End of Month",(IF(EDATE(MIN(Table4[[#All],[Loan Date]]), ROW()-ROW($Q$6)) > MAX(Table4[[#All],[Loan Payment End Date]]), "", (EOMONTH(EDATE(MIN(Table4[[#All],[Loan Date]]), ROW()-ROW($Q$6)),IF(31 - DAY(MIN(Table4[[#All],[Loan Date]])) <= $E$15, 1, 0))))), IF($E$14="Start of Month",(IF(EDATE(MIN(Table4[[#All],[Loan Date]]), ROW()-ROW($Q$6)) > MAX(Table4[[#All],[Loan Payment End Date]]), "", (EOMONTH(EDATE(MIN(Table4[[#All],[Loan Date]]), ROW()-ROW($Q$6)),IF(31 - DAY(MIN(Table4[[#All],[Loan Date]])) <= $E$15, 1, 0))) + 1 ))) ) ) -> 45474 | R10: =IF(Table5[[#This Row],[Payment date]]<>"", SUMIFS(Table4[[#All],[Loan Amount]],Table4[[#All],[Loan Date]],"<="&Table5[[#This Row],[Payment date]]) - SUM($S$5:S9)- SUM($W$5:W9),"") -> 41333.333 | S10: =IF(Table5[[#This Row],[Payment date]]<>"",SUM('Individual Loan Schedule'!C13:HR13) - SUM('Early Payments'!D13:HS13),"") -> 11666.667 | T10: {=IF(Table5[[#This Row],[Payment date]]<>"",((SUMIFS(Table4[Loan Amount],Table4[Loan Payment Start Date],"<"&Table5[[#This Row],[Payment date]]) - SUM($S$5:$S9) - SUM($W$5:W9))*InterestRate*(Table5[[#This Row],[Payment date]] - IF($E$14="End of Month",EOMONTH(Table5[[#This Row],[Payment date]],-1), IF($E$14="Mid of Month",EOMONTH(Table5[[#This Row],[Payment date]],-2)+15, IF($E$14="Start of Month",EOMONTH(Table5[[#This Row],[Payment date]],-2) + 1))) )/360) + (SUM(IFERROR((IF(Table4[Loan Payment Start Date]=Table5[[#This Row],[Payment date]],Table4[Loan Amount],"")*(Table4[Loan Payment Start Date]-Table4[Loan Date])*InterestRate/360),0),0)),"")} -> 620 | U10: =IF(Table5[[#This Row],[Payment date]]<>"",SUMIFS(Table4[[#All],[Loan Amount]],Table4[[#All],[Loan Payment Start Date]],"="&Table5[[#This Row],[Payment date]])*($E$7),"") -> 0 | V10: {=IF(Table5[[#This Row],[Payment date]]<>"",IF(Table5[[#This Row],[Payment date]]=MIN(Table4[[#All],[Loan Payment Start Date]]),$E$8+$E$10*LoanAmount,0) + IF(Table5[[#This Row],[Payment date]] =MIN(_xlfn._xlws.FILTER(Table5[Payment date],(Table5[Payment date]>=EDATE(LoanStartDate,12*DATEDIF(LoanStartDate,Table5[[#This Row],[Payment date]],"y")))*(Table5[Beginning balance]<>0))), $E$9*LoanAmount,0),"")} -> 0 | Y10: =IF(Table5[[#This Row],[Payment date]]<>"",(SUMIFS(Table4[Loan Amount],Table4[Loan Payment Start Date],"<="&Table5[[#This Row],[Payment date]]) - SUM($S$5:$S9) - - SUM($W$5:W9))*Table5[[#This Row],[Delay in Payment ]]*($E$16+ InterestRate)/365,"") -> 0 | Z10: =IF(Table5[[#This Row],[Payment date]]<>"",Table5[[#This Row],[Payment date]]+Table5[[#This Row],[Delay in Payment ]],"") -> 45474 | AA10: =IF(Table5[[#This Row],[Payment date]]<>"",Table5[[#This Row],[Beginning balance]]-Table5[[#This Row],[Principal Payment]] - Table5[[#This Row],[Extra Payment]],"") -> 29666.667 | AB10: =IF(Table5[[#This Row],[Payment date]]<>"",Table5[[#This Row],[Draw Fee]]+Table5[[#This Row],[Interest]]+Table5[[#This Row],[Principal Payment]]+Table5[[#This Row],[Overdue Interest]],"") -> 12286.667
B11: Loan period in years | E11: 1 | G11: =IFERROR(RANK(Table4[[#This Row],[Loan Date]],Table4[[#All],[Loan Date]],1) +COUNTIF($I$6:I11,I11)-1,"") | J11: =IF(Table4[[#This Row],[Loan Date]]<>"",IF($E$14 = "End of Month", EOMONTH(Table4[[#This Row],[Loan Date]],IF(DAY(EOMONTH(Table4[[#This Row],[Loan Date]],0)) - DAY(Table4[[#This Row],[Loan Date]])<=$E$15,1,0)),IF($E$14 = "Mid of Month", EOMONTH(Table4[[#This Row],[Loan Date]],IF(15 - DAY(Table4[[#This Row],[Loan Date]])<=$E$15,0,-1))+15,IF($E$14 = "Start of Month", EOMONTH(Table4[[#This Row],[Loan Date]],IF(DAY(EOMONTH(Table4[[#This Row],[Loan Date]],0)) - DAY(Table4[[#This Row],[Loan Date]])<=$E$15,1,0))) + 1)),"") | K11: =IF(Table4[[#This Row],[Loan Date]]<>"", IF($E$14 = "End of Month", EOMONTH(Table4[[#This Row],[Loan Date]],6+IF(DAY(EOMONTH(Table4[[#This Row],[Loan Date]],0)) - DAY(Table4[[#This Row],[Loan Date]])<=$E$15,0,-1)), IF($E$14 = "Mid of Month", EOMONTH(Table4[[#This Row],[Loan Date]],6+IF(15 - DAY(Table4[[#This Row],[Loan Date]])<=$E$15,-1,-2))+15, IF($E$14 = "Start of Month", EOMONTH(Table4[[#This Row],[Loan Date]],6+IF(DAY(EOMONTH(Table4[[#This Row],[Loan Date]],0)) - DAY(Table4[[#This Row],[Loan Date]])<=$E$15,0,-1)) + 1) ) ),"") | L11: =IF(Table4[[#This Row],[Loan Date]]<>"",Table4[[#This Row],[Loan Amount]]/PaymentsPerYear,"") | M11: {=IF(Table4[[#This Row],[Loan Date]]<>"", ((Table4[[#This Row],[Loan Payment Start Date]]-Table4[[#This Row],[Loan Date]])*Table4[[#This Row],[Loan Amount]]*InterestRate/360) + SUM((_xlfn.SEQUENCE(6, 1, Table4[[#This Row],[Loan Amount]]-Table4[[#This Row],[Loan Amount]]/6, -Table4[[#This Row],[Loan Amount]]/6))* (IF($E$14 = "End of Month", EOMONTH(EDATE(Table4[[#This Row],[Loan Payment Start Date]],_xlfn.SEQUENCE(6,1,1,1)),0),IF($E$14 = "Mid of Month",EDATE(Table4[[#This Row],[Loan Payment Start Date]],_xlfn.SEQUENCE(6,1,1,1)), IF($E$14 = "Start of Month", EOMONTH(EDATE(Table4[[#This Row],[Loan Payment Start Date]],_xlfn.SEQUENCE(6,1,1,1)),-1)+1))) - IF($E$14 = "End of Month", EOMONTH(EDATE(Table4[[#This Row],[Loan Payment Start Date]],_xlfn.SEQUENCE(6,1,1,1)),-1),IF($E$14 = "Mid of Month",EDATE(Table4[[#This Row],[Loan Payment Start Date]],_xlfn.SEQUENCE(6,1,0,1)), IF($E$14 = "Start of Month", EOMONTH(EDATE(Table4[[#This Row],[Loan Payment Start Date]],_xlfn.SEQUENCE(6,1,1,1)),-2)+1))))*InterestRate/360),"")} | N11: =IF(Table4[[#This Row],[Loan Amount]]<>"", IF((LoanAmount - (SUMIFS(Table4[Loan Amount],Table4[Loan Date],"<"&Table4[[#This Row],[Loan Date]]) -SUMIFS(Table5[Principal Payment],Table5[Payment date],"<="&Table4[[#This Row],[Loan Date]]) - SUMIFS(Table5[Extra Payment],Table5[Payment date],"<="&Table4[[#This Row],[Loan Date]])) > Table4[[#This Row],[Loan Amount]]),"Yes","No"),"") | O11: =IF(Table4[[#This Row],[Loan Amount]]<>"", LoanAmount - (SUMIFS(Table4[Loan Amount],Table4[Loan Date],"<"&Table4[[#This Row],[Loan Date]]) -SUMIFS(Table5[Principal Payment],Table5[Payment date],"<="&Table4[[#This Row],[Loan Date]]) - SUMIFS(Table5[Extra Payment],Table5[Payment date],"<="&Table4[[#This Row],[Loan Date]])) - Table4[[#This Row],[Loan Amount]],"") | Q11: =IF($E$14="Mid of Month",(IF(EDATE(MIN(Table4[[#All],[Loan Date]]), ROW()-ROW($Q$6)) > EDATE(MAX(Table4[[#All],[Loan Payment End Date]]),1), "", (EOMONTH(EDATE(MIN(Table4[[#All],[Loan Date]]), ROW()-ROW($Q$6)),IF(DAY(EOMONTH(MIN(Table4[[#All],[Loan Date]]),0)) - DAY(MIN(Table4[[#All],[Loan Date]])) <= $E$15, 0, -1))+ 15))), IF($E$14="End of Month",(IF(EDATE(MIN(Table4[[#All],[Loan Date]]), ROW()-ROW($Q$6)) > MAX(Table4[[#All],[Loan Payment End Date]]), "", (EOMONTH(EDATE(MIN(Table4[[#All],[Loan Date]]), ROW()-ROW($Q$6)),IF(31 - DAY(MIN(Table4[[#All],[Loan Date]])) <= $E$15, 1, 0))))), IF($E$14="Start of Month",(IF(EDATE(MIN(Table4[[#All],[Loan Date]]), ROW()-ROW($Q$6)) > MAX(Table4[[#All],[Loan Payment End Date]]), "", (EOMONTH(EDATE(MIN(Table4[[#All],[Loan Date]]), ROW()-ROW($Q$6)),IF(31 - DAY(MIN(Table4[[#All],[Loan Date]])) <= $E$15, 1, 0))) + 1 ))) ) ) -> 45505 | R11: =IF(Table5[[#This Row],[Payment date]]<>"", SUMIFS(Table4[[#All],[Loan Amount]],Table4[[#All],[Loan Date]],"<="&Table5[[#This Row],[Payment date]]) - SUM($S$5:S10)- SUM($W$5:W10),"") -> 29666.667 | S11: =IF(Table5[[#This Row],[Payment date]]<>"",SUM('Individual Loan Schedule'!C14:HR14) - SUM('Early Payments'!D14:HS14),"") -> 11666.667 | T11: {=IF(Table5[[#This Row],[Payment date]]<>"",((SUMIFS(Table4[Loan Amount],Table4[Loan Payment Start Date],"<"&Table5[[#This Row],[Payment date]]) - SUM($S$5:$S10) - SUM($W$5:W10))*InterestRate*(Table5[[#This Row],[Payment date]] - IF($E$14="End of Month",EOMONTH(Table5[[#This Row],[Payment date]],-1), IF($E$14="Mid of Month",EOMONTH(Table5[[#This Row],[Payment date]],-2)+15, IF($E$14="Start of Month",EOMONTH(Table5[[#This Row],[Payment date]],-2) + 1))) )/360) + (SUM(IFERROR((IF(Table4[Loan Payment Start Date]=Table5[[#This Row],[Payment date]],Table4[Loan Amount],"")*(Table4[Loan Payment Start Date]-Table4[Loan Date])*InterestRate/360),0),0)),"")} -> 459.83333 | U11: =IF(Table5[[#This Row],[Payment date]]<>"",SUMIFS(Table4[[#All],[Loan Amount]],Table4[[#All],[Loan Payment Start Date]],"="&Table5[[#This Row],[Payment date]])*($E$7),"") -> 0 | V11: {=IF(Table5[[#This Row],[Payment date]]<>"",IF(Table5[[#This Row],[Payment date]]=MIN(Table4[[#All],[Loan Payment Start Date]]),$E$8+$E$10*LoanAmount,0) + IF(Table5[[#This Row],[Payment date]] =MIN(_xlfn._xlws.FILTER(Table5[Payment date],(Table5[Payment date]>=EDATE(LoanStartDate,12*DATEDIF(LoanStartDate,Table5[[#This Row],[Payment date]],"y")))*(Table5[Beginning balance]<>0))), $E$9*LoanAmount,0),"")} -> 0 | Y11: =IF(Table5[[#This Row],[Payment date]]<>"",(SUMIFS(Table4[Loan Amount],Table4[Loan Payment Start Date],"<="&Table5[[#This Row],[Payment date]]) - SUM($S$5:$S10) - - SUM($W$5:W10))*Table5[[#This Row],[Delay in Payment ]]*($E$16+ InterestRate)/365,"") -> 0 | Z11: =IF(Table5[[#This Row],[Payment date]]<>"",Table5[[#This Row],[Payment date]]+Table5[[#This Row],[Delay in Payment ]],"") -> 45505 | AA11: =IF(Table5[[#This Row],[Payment date]]<>"",Table5[[#This Row],[Beginning balance]]-Table5[[#This Row],[Principal Payment]] - Table5[[#This Row],[Extra Payment]],"") -> 18000 | AB11: =IF(Table5[[#This Row],[Payment date]]<>"",Table5[[#This Row],[Draw Fee]]+Table5[[#This Row],[Interest]]+Table5[[#This Row],[Principal Payment]]+Table5[[#This Row],[Overdue Interest]],"") -> 12126.5
B12: Max Number of payments | E12: 6 | G12: =IFERROR(RANK(Table4[[#This Row],[Loan Date]],Table4[[#All],[Loan Date]],1) +COUNTIF($I$6:I12,I12)-1,"") | J12: =IF(Table4[[#This Row],[Loan Date]]<>"",IF($E$14 = "End of Month", EOMONTH(Table4[[#This Row],[Loan Date]],IF(DAY(EOMONTH(Table4[[#This Row],[Loan Date]],0)) - DAY(Table4[[#This Row],[Loan Date]])<=$E$15,1,0)),IF($E$14 = "Mid of Month", EOMONTH(Table4[[#This Row],[Loan Date]],IF(15 - DAY(Table4[[#This Row],[Loan Date]])<=$E$15,0,-1))+15,IF($E$14 = "Start of Month", EOMONTH(Table4[[#This Row],[Loan Date]],IF(DAY(EOMONTH(Table4[[#This Row],[Loan Date]],0)) - DAY(Table4[[#This Row],[Loan Date]])<=$E$15,1,0))) + 1)),"") | K12: =IF(Table4[[#This Row],[Loan Date]]<>"", IF($E$14 = "End of Month", EOMONTH(Table4[[#This Row],[Loan Date]],6+IF(DAY(EOMONTH(Table4[[#This Row],[Loan Date]],0)) - DAY(Table4[[#This Row],[Loan Date]])<=$E$15,0,-1)), IF($E$14 = "Mid of Month", EOMONTH(Table4[[#This Row],[Loan Date]],6+IF(15 - DAY(Table4[[#This Row],[Loan Date]])<=$E$15,-1,-2))+15, IF($E$14 = "Start of Month", EOMONTH(Table4[[#This Row],[Loan Date]],6+IF(DAY(EOMONTH(Table4[[#This Row],[Loan Date]],0)) - DAY(Table4[[#This Row],[Loan Date]])<=$E$15,0,-1)) + 1) ) ),"") | L12: =IF(Table4[[#This Row],[Loan Date]]<>"",Table4[[#This Row],[Loan Amount]]/PaymentsPerYear,"") | M12: {=IF(Table4[[#This Row],[Loan Date]]<>"", ((Table4[[#This Row],[Loan Payment Start Date]]-Table4[[#This Row],[Loan Date]])*Table4[[#This Row],[Loan Amount]]*InterestRate/360) + SUM((_xlfn.SEQUENCE(6, 1, Table4[[#This Row],[Loan Amount]]-Table4[[#This Row],[Loan Amount]]/6, -Table4[[#This Row],[Loan Amount]]/6))* (IF($E$14 = "End of Month", EOMONTH(EDATE(Table4[[#This Row],[Loan Payment Start Date]],_xlfn.SEQUENCE(6,1,1,1)),0),IF($E$14 = "Mid of Month",EDATE(Table4[[#This Row],[Loan Payment Start Date]],_xlfn.SEQUENCE(6,1,1,1)), IF($E$14 = "Start of Month", EOMONTH(EDATE(Table4[[#This Row],[Loan Payment Start Date]],_xlfn.SEQUENCE(6,1,1,1)),-1)+1))) - IF($E$14 = "End of Month", EOMONTH(EDATE(Table4[[#This Row],[Loan Payment Start Date]],_xlfn.SEQUENCE(6,1,1,1)),-1),IF($E$14 = "Mid of Month",EDATE(Table4[[#This Row],[Loan Payment Start Date]],_xlfn.SEQUENCE(6,1,0,1)), IF($E$14 = "Start of Month", EOMONTH(EDATE(Table4[[#This Row],[Loan Payment Start Date]],_xlfn.SEQUENCE(6,1,1,1)),-2)+1))))*InterestRate/360),"")} | N12: =IF(Table4[[#This Row],[Loan Amount]]<>"", IF((LoanAmount - (SUMIFS(Table4[Loan Amount],Table4[Loan Date],"<"&Table4[[#This Row],[Loan Date]]) -SUMIFS(Table5[Principal Payment],Table5[Payment date],"<="&Table4[[#This Row],[Loan Date]]) - SUMIFS(Table5[Extra Payment],Table5[Payment date],"<="&Table4[[#This Row],[Loan Date]])) > Table4[[#This Row],[Loan Amount]]),"Yes","No"),"") | O12: =IF(Table4[[#This Row],[Loan Amount]]<>"", LoanAmount - (SUMIFS(Table4[Loan Amount],Table4[Loan Date],"<"&Table4[[#This Row],[Loan Date]]) -SUMIFS(Table5[Principal Payment],Table5[Payment date],"<="&Table4[[#This Row],[Loan Date]]) - SUMIFS(Table5[Extra Payment],Table5[Payment date],"<="&Table4[[#This Row],[Loan Date]])) - Table4[[#This Row],[Loan Amount]],"") | Q12: =IF($E$14="Mid of Month",(IF(EDATE(MIN(Table4[[#All],[Loan Date]]), ROW()-ROW($Q$6)) > EDATE(MAX(Table4[[#All],[Loan Payment End Date]]),1), "", (EOMONTH(EDATE(MIN(Table4[[#All],[Loan Date]]), ROW()-ROW($Q$6)),IF(DAY(EOMONTH(MIN(Table4[[#All],[Loan Date]]),0)) - DAY(MIN(Table4[[#All],[Loan Date]])) <= $E$15, 0, -1))+ 15))), IF($E$14="End of Month",(IF(EDATE(MIN(Table4[[#All],[Loan Date]]), ROW()-ROW($Q$6)) > MAX(Table4[[#All],[Loan Payment End Date]]), "", (EOMONTH(EDATE(MIN(Table4[[#All],[Loan Date]]), ROW()-ROW($Q$6)),IF(31 - DAY(MIN(Table4[[#All],[Loan Date]])) <= $E$15, 1, 0))))), IF($E$14="Start of Month",(IF(EDATE(MIN(Table4[[#All],[Loan Date]]), ROW()-ROW($Q$6)) > MAX(Table4[[#All],[Loan Payment End Date]]), "", (EOMONTH(EDATE(MIN(Table4[[#All],[Loan Date]]), ROW()-ROW($Q$6)),IF(31 - DAY(MIN(Table4[[#All],[Loan Date]])) <= $E$15, 1, 0))) + 1 ))) ) ) -> 45536 | R12: =IF(Table5[[#This Row],[Payment date]]<>"", SUMIFS(Table4[[#All],[Loan Amount]],Table4[[#All],[Loan Date]],"<="&Table5[[#This Row],[Payment date]]) - SUM($S$5:S11)- SUM($W$5:W11),"") -> 18000 | S12: =IF(Table5[[#This Row],[Payment date]]<>"",SUM('Individual Loan Schedule'!C15:HR15) - SUM('Early Payments'!D15:HS15),"") -> 9666.6667 | T12: {=IF(Table5[[#This Row],[Payment date]]<>"",((SUMIFS(Table4[Loan Amount],Table4[Loan Payment Start Date],"<"&Table5[[#This Row],[Payment date]]) - SUM($S$5:$S11) - SUM($W$5:W11))*InterestRate*(Table5[[#This Row],[Payment date]] - IF($E$14="End of Month",EOMONTH(Table5[[#This Row],[Payment date]],-1), IF($E$14="Mid of Month",EOMONTH(Table5[[#This Row],[Payment date]],-2)+15, IF($E$14="Start of Month",EOMONTH(Table5[[#This Row],[Payment date]],-2) + 1))) )/360) + (SUM(IFERROR((IF(Table4[Loan Payment Start Date]=Table5[[#This Row],[Payment date]],Table4[Loan Amount],"")*(Table4[Loan Payment Start Date]-Table4[Loan Date])*InterestRate/360),0),0)),"")} -> 279 | U12: =IF(Table5[[#This Row],[Payment date]]<>"",SUMIFS(Table4[[#All],[Loan Amount]],Table4[[#All],[Loan Payment Start Date]],"="&Table5[[#This Row],[Payment date]])*($E$7),"") -> 0 | V12: {=IF(Table5[[#This Row],[Payment date]]<>"",IF(Table5[[#This Row],[Payment date]]=MIN(Table4[[#All],[Loan Payment Start Date]]),$E$8+$E$10*LoanAmount,0) + IF(Table5[[#This Row],[Payment date]] =MIN(_xlfn._xlws.FILTER(Table5[Payment date],(Table5[Payment date]>=EDATE(LoanStartDate,12*DATEDIF(LoanStartDate,Table5[[#This Row],[Payment date]],"y")))*(Table5[Beginning balance]<>0))), $E$9*LoanAmount,0),"")} -> 0 | Y12: =IF(Table5[[#This Row],[Payment date]]<>"",(SUMIFS(Table4[Loan Amount],Table4[Loan Payment Start Date],"<="&Table5[[#This Row],[Payment date]]) - SUM($S$5:$S11) - - SUM($W$5:W11))*Table5[[#This Row],[Delay in Payment ]]*($E$16+ InterestRate)/365,"") -> 0 | Z12: =IF(Table5[[#This Row],[Payment date]]<>"",Table5[[#This Row],[Payment date]]+Table5[[#This Row],[Delay in Payment ]],"") -> 45536 | AA12: =IF(Table5[[#This Row],[Payment date]]<>"",Table5[[#This Row],[Beginning balance]]-Table5[[#This Row],[Principal Payment]] - Table5[[#This Row],[Extra Payment]],"") -> 8333.3333 | AB12: =IF(Table5[[#This Row],[Payment date]]<>"",Table5[[#This Row],[Draw Fee]]+Table5[[#This Row],[Interest]]+Table5[[#This Row],[Principal Payment]]+Table5[[#This Row],[Overdue Interest]],"") -> 9945.6667
B13: Onboarding Date | E13: 45292 | G13: =IFERROR(RANK(Table4[[#This Row],[Loan Date]],Table4[[#All],[Loan Date]],1) +COUNTIF($I$6:I13,I13)-1,"") | J13: =IF(Table4[[#This Row],[Loan Date]]<>"",IF($E$14 = "End of Month", EOMONTH(Table4[[#This Row],[Loan Date]],IF(DAY(EOMONTH(Table4[[#This Row],[Loan Date]],0)) - DAY(Table4[[#This Row],[Loan Date]])<=$E$15,1,0)),IF($E$14 = "Mid of Month", EOMONTH(Table4[[#This Row],[Loan Date]],IF(15 - DAY(Table4[[#This Row],[Loan Date]])<=$E$15,0,-1))+15,IF($E$14 = "Start of Month", EOMONTH(Table4[[#This Row],[Loan Date]],IF(DAY(EOMONTH(Table4[[#This Row],[Loan Date]],0)) - DAY(Table4[[#This Row],[Loan Date]])<=$E$15,1,0))) + 1)),"") | K13: =IF(Table4[[#This Row],[Loan Date]]<>"", IF($E$14 = "End of Month", EOMONTH(Table4[[#This Row],[Loan Date]],6+IF(DAY(EOMONTH(Table4[[#This Row],[Loan Date]],0)) - DAY(Table4[[#This Row],[Loan Date]])<=$E$15,0,-1)), IF($E$14 = "Mid of Month", EOMONTH(Table4[[#This Row],[Loan Date]],6+IF(15 - DAY(Table4[[#This Row],[Loan Date]])<=$E$15,-1,-2))+15, IF($E$14 = "Start of Month", EOMONTH(Table4[[#This Row],[Loan Date]],6+IF(DAY(EOMONTH(Table4[[#This Row],[Loan Date]],0)) - DAY(Table4[[#This Row],[Loan Date]])<=$E$15,0,-1)) + 1) ) ),"") | L13: =IF(Table4[[#This Row],[Loan Date]]<>"",Table4[[#This Row],[Loan Amount]]/PaymentsPerYear,"") | M13: {=IF(Table4[[#This Row],[Loan Date]]<>"", ((Table4[[#This Row],[Loan Payment Start Date]]-Table4[[#This Row],[Loan Date]])*Table4[[#This Row],[Loan Amount]]*InterestRate/360) + SUM((_xlfn.SEQUENCE(6, 1, Table4[[#This Row],[Loan Amount]]-Table4[[#This Row],[Loan Amount]]/6, -Table4[[#This Row],[Loan Amount]]/6))* (IF($E$14 = "End of Month", EOMONTH(EDATE(Table4[[#This Row],[Loan Payment Start Date]],_xlfn.SEQUENCE(6,1,1,1)),0),IF($E$14 = "Mid of Month",EDATE(Table4[[#This Row],[Loan Payment Start Date]],_xlfn.SEQUENCE(6,1,1,1)), IF($E$14 = "Start of Month", EOMONTH(EDATE(Table4[[#This Row],[Loan Payment Start Date]],_xlfn.SEQUENCE(6,1,1,1)),-1)+1))) - IF($E$14 = "End of Month", EOMONTH(EDATE(Table4[[#This Row],[Loan Payment Start Date]],_xlfn.SEQUENCE(6,1,1,1)),-1),IF($E$14 = "Mid of Month",EDATE(Table4[[#This Row],[Loan Payment Start Date]],_xlfn.SEQUENCE(6,1,0,1)), IF($E$14 = "Start of Month", EOMONTH(EDATE(Table4[[#This Row],[Loan Payment Start Date]],_xlfn.SEQUENCE(6,1,1,1)),-2)+1))))*InterestRate/360),"")} | N13: =IF(Table4[[#This Row],[Loan Amount]]<>"", IF((LoanAmount - (SUMIFS(Table4[Loan Amount],Table4[Loan Date],"<"&Table4[[#This Row],[Loan Date]]) -SUMIFS(Table5[Principal Payment],Table5[Payment date],"<="&Table4[[#This Row],[Loan Date]]) - SUMIFS(Table5[Extra Payment],Table5[Payment date],"<="&Table4[[#This Row],[Loan Date]])) > Table4[[#This Row],[Loan Amount]]),"Yes","No"),"") | O13: =IF(Table4[[#This Row],[Loan Amount]]<>"", LoanAmount - (SUMIFS(Table4[Loan Amount],Table4[Loan Date],"<"&Table4[[#This Row],[Loan Date]]) -SUMIFS(Table5[Principal Payment],Table5[Payment date],"<="&Table4[[#This Row],[Loan Date]]) - SUMIFS(Table5[Extra Payment],Table5[Payment date],"<="&Table4[[#This Row],[Loan Date]])) - Table4[[#This Row],[Loan Amount]],"") | Q13: =IF($E$14="Mid of Month",(IF(EDATE(MIN(Table4[[#All],[Loan Date]]), ROW()-ROW($Q$6)) > EDATE(MAX(Table4[[#All],[Loan Payment End Date]]),1), "", (EOMONTH(EDATE(MIN(Table4[[#All],[Loan Date]]), ROW()-ROW($Q$6)),IF(DAY(EOMONTH(MIN(Table4[[#All],[Loan Date]]),0)) - DAY(MIN(Table4[[#All],[Loan Date]])) <= $E$15, 0, -1))+ 15))), IF($E$14="End of Month",(IF(EDATE(MIN(Table4[[#All],[Loan Date]]), ROW()-ROW($Q$6)) > MAX(Table4[[#All],[Loan Payment End Date]]), "", (EOMONTH(EDATE(MIN(Table4[[#All],[Loan Date]]), ROW()-ROW($Q$6)),IF(31 - DAY(MIN(Table4[[#All],[Loan Date]])) <= $E$15, 1, 0))))), IF($E$14="Start of Month",(IF(EDATE(MIN(Table4[[#All],[Loan Date]]), ROW()-ROW($Q$6)) > MAX(Table4[[#All],[Loan Payment End Date]]), "", (EOMONTH(EDATE(MIN(Table4[[#All],[Loan Date]]), ROW()-ROW($Q$6)),IF(31 - DAY(MIN(Table4[[#All],[Loan Date]])) <= $E$15, 1, 0))) + 1 ))) ) ) -> 45566 | R13: =IF(Table5[[#This Row],[Payment date]]<>"", SUMIFS(Table4[[#All],[Loan Amount]],Table4[[#All],[Loan Date]],"<="&Table5[[#This Row],[Payment date]]) - SUM($S$5:S12)- SUM($W$5:W12),"") -> 8333.3333 | S13: =IF(Table5[[#This Row],[Payment date]]<>"",SUM('Individual Loan Schedule'!C16:HR16) - SUM('Early Payments'!D16:HS16),"") -> 8333.3333 | T13: {=IF(Table5[[#This Row],[Payment date]]<>"",((SUMIFS(Table4[Loan Amount],Table4[Loan Payment Start Date],"<"&Table5[[#This Row],[Payment date]]) - SUM($S$5:$S12) - SUM($W$5:W12))*InterestRate*(Table5[[#This Row],[Payment date]] - IF($E$14="End of Month",EOMONTH(Table5[[#This Row],[Payment date]],-1), IF($E$14="Mid of Month",EOMONTH(Table5[[#This Row],[Payment date]],-2)+15, IF($E$14="Start of Month",EOMONTH(Table5[[#This Row],[Payment date]],-2) + 1))) )/360) + (SUM(IFERROR((IF(Table4[Loan Payment Start Date]=Table5[[#This Row],[Payment date]],Table4[Loan Amount],"")*(Table4[Loan Payment Start Date]-Table4[Loan Date])*InterestRate/360),0),0)),"")} -> 125 | U13: =IF(Table5[[#This Row],[Payment date]]<>"",SUMIFS(Table4[[#All],[Loan Amount]],Table4[[#All],[Loan Payment Start Date]],"="&Table5[[#This Row],[Payment date]])*($E$7),"") -> 0 | V13: {=IF(Table5[[#This Row],[Payment date]]<>"",IF(Table5[[#This Row],[Payment date]]=MIN(Table4[[#All],[Loan Payment Start Date]]),$E$8+$E$10*LoanAmount,0) + IF(Table5[[#This Row],[Payment date]] =MIN(_xlfn._xlws.FILTER(Table5[Payment date],(Table5[Payment date]>=EDATE(LoanStartDate,12*DATEDIF(LoanStartDate,Table5[[#This Row],[Payment date]],"y")))*(Table5[Beginning balance]<>0))), $E$9*LoanAmount,0),"")} -> 0 | Y13: =IF(Table5[[#This Row],[Payment date]]<>"",(SUMIFS(Table4[Loan Amount],Table4[Loan Payment Start Date],"<="&Table5[[#This Row],[Payment date]]) - SUM($S$5:$S12) - - SUM($W$5:W12))*Table5[[#This Row],[Delay in Payment ]]*($E$16+ InterestRate)/365,"") -> 0 | Z13: =IF(Table5[[#This Row],[Payment date]]<>"",Table5[[#This Row],[Payment date]]+Table5[[#This Row],[Delay in Payment ]],"") -> 45566 | AA13: =IF(Table5[[#This Row],[Payment date]]<>"",Table5[[#This Row],[Beginning balance]]-Table5[[#This Row],[Principal Payment]] - Table5[[#This Row],[Extra Payment]],"") -> 1.0913936e-11 | AB13: =IF(Table5[[#This Row],[Payment date]]<>"",Table5[[#This Row],[Draw Fee]]+Table5[[#This Row],[Interest]]+Table5[[#This Row],[Principal Payment]]+Table5[[#This Row],[Overdue Interest]],"") -> 8458.3333
B14: Preferred Payment Time (Mid of Month/ End of Month) | E14: Start of Month | G14: =IFERROR(RANK(Table4[[#This Row],[Loan Date]],Table4[[#All],[Loan Date]],1) +COUNTIF($I$6:I14,I14)-1,"") | J14: =IF(Table4[[#This Row],[Loan Date]]<>"",IF($E$14 = "End of Month", EOMONTH(Table4[[#This Row],[Loan Date]],IF(DAY(EOMONTH(Table4[[#This Row],[Loan Date]],0)) - DAY(Table4[[#This Row],[Loan Date]])<=$E$15,1,0)),IF($E$14 = "Mid of Month", EOMONTH(Table4[[#This Row],[Loan Date]],IF(15 - DAY(Table4[[#This Row],[Loan Date]])<=$E$15,0,-1))+15,IF($E$14 = "Start of Month", EOMONTH(Table4[[#This Row],[Loan Date]],IF(DAY(EOMONTH(Table4[[#This Row],[Loan Date]],0)) - DAY(Table4[[#This Row],[Loan Date]])<=$E$15,1,0))) + 1)),"") | K14: =IF(Table4[[#This Row],[Loan Date]]<>"", IF($E$14 = "End of Month", EOMONTH(Table4[[#This Row],[Loan Date]],6+IF(DAY(EOMONTH(Table4[[#This Row],[Loan Date]],0)) - DAY(Table4[[#This Row],[Loan Date]])<=$E$15,0,-1)), IF($E$14 = "Mid of Month", EOMONTH(Table4[[#This Row],[Loan Date]],6+IF(15 - DAY(Table4[[#This Row],[Loan Date]])<=$E$15,-1,-2))+15, IF($E$14 = "Start of Month", EOMONTH(Table4[[#This Row],[Loan Date]],6+IF(DAY(EOMONTH(Table4[[#This Row],[Loan Date]],0)) - DAY(Table4[[#This Row],[Loan Date]])<=$E$15,0,-1)) + 1) ) ),"") | L14: =IF(Table4[[#This Row],[Loan Date]]<>"",Table4[[#This Row],[Loan Amount]]/PaymentsPerYear,"") | M14: {=IF(Table4[[#This Row],[Loan Date]]<>"", ((Table4[[#This Row],[Loan Payment Start Date]]-Table4[[#This Row],[Loan Date]])*Table4[[#This Row],[Loan Amount]]*InterestRate/360) + SUM((_xlfn.SEQUENCE(6, 1, Table4[[#This Row],[Loan Amount]]-Table4[[#This Row],[Loan Amount]]/6, -Table4[[#This Row],[Loan Amount]]/6))* (IF($E$14 = "End of Month", EOMONTH(EDATE(Table4[[#This Row],[Loan Payment Start Date]],_xlfn.SEQUENCE(6,1,1,1)),0),IF($E$14 = "Mid of Month",EDATE(Table4[[#This Row],[Loan Payment Start Date]],_xlfn.SEQUENCE(6,1,1,1)), IF($E$14 = "Start of Month", EOMONTH(EDATE(Table4[[#This Row],[Loan Payment Start Date]],_xlfn.SEQUENCE(6,1,1,1)),-1)+1))) - IF($E$14 = "End of Month", EOMONTH(EDATE(Table4[[#This Row],[Loan Payment Start Date]],_xlfn.SEQUENCE(6,1,1,1)),-1),IF($E$14 = "Mid of Month",EDATE(Table4[[#This Row],[Loan Payment Start Date]],_xlfn.SEQUENCE(6,1,0,1)), IF($E$14 = "Start of Month", EOMONTH(EDATE(Table4[[#This Row],[Loan Payment Start Date]],_xlfn.SEQUENCE(6,1,1,1)),-2)+1))))*InterestRate/360),"")} | N14: =IF(Table4[[#This Row],[Loan Amount]]<>"", IF((LoanAmount - (SUMIFS(Table4[Loan Amount],Table4[Loan Date],"<"&Table4[[#This Row],[Loan Date]]) -SUMIFS(Table5[Principal Payment],Table5[Payment date],"<="&Table4[[#This Row],[Loan Date]]) - SUMIFS(Table5[Extra Payment],Table5[Payment date],"<="&Table4[[#This Row],[Loan Date]])) > Table4[[#This Row],[Loan Amount]]),"Yes","No"),"") | O14: =IF(Table4[[#This Row],[Loan Amount]]<>"", LoanAmount - (SUMIFS(Table4[Loan Amount],Table4[Loan Date],"<"&Table4[[#This Row],[Loan Date]]) -SUMIFS(Table5[Principal Payment],Table5[Payment date],"<="&Table4[[#This Row],[Loan Date]]) - SUMIFS(Table5[Extra Payment],Table5[Payment date],"<="&Table4[[#This Row],[Loan Date]])) - Table4[[#This Row],[Loan Amount]],"") | Q14: =IF($E$14="Mid of Month",(IF(EDATE(MIN(Table4[[#All],[Loan Date]]), ROW()-ROW($Q$6)) > EDATE(MAX(Table4[[#All],[Loan Payment End Date]]),1), "", (EOMONTH(EDATE(MIN(Table4[[#All],[Loan Date]]), ROW()-ROW($Q$6)),IF(DAY(EOMONTH(MIN(Table4[[#All],[Loan Date]]),0)) - DAY(MIN(Table4[[#All],[Loan Date]])) <= $E$15, 0, -1))+ 15))), IF($E$14="End of Month",(IF(EDATE(MIN(Table4[[#All],[Loan Date]]), ROW()-ROW($Q$6)) > MAX(Table4[[#All],[Loan Payment End Date]]), "", (EOMONTH(EDATE(MIN(Table4[[#All],[Loan Date]]), ROW()-ROW($Q$6)),IF(31 - DAY(MIN(Table4[[#All],[Loan Date]])) <= $E$15, 1, 0))))), IF($E$14="Start of Month",(IF(EDATE(MIN(Table4[[#All],[Loan Date]]), ROW()-ROW($Q$6)) > MAX(Table4[[#All],[Loan Payment End Date]]), "", (EOMONTH(EDATE(MIN(Table4[[#All],[Loan Date]]), ROW()-ROW($Q$6)),IF(31 - DAY(MIN(Table4[[#All],[Loan Date]])) <= $E$15, 1, 0))) + 1 ))) ) ) -> 45597 | R14: =IF(Table5[[#This Row],[Payment date]]<>"", SUMIFS(Table4[[#All],[Loan Amount]],Table4[[#All],[Loan Date]],"<="&Table5[[#This Row],[Payment date]]) - SUM($S$5:S13)- SUM($W$5:W13),"") -> 1.4551915e-11 | S14: =IF(Table5[[#This Row],[Payment date]]<>"",SUM('Individual Loan Schedule'!C17:HR17) - SUM('Early Payments'!D17:HS17),"") -> 0 | T14: {=IF(Table5[[#This Row],[Payment date]]<>"",((SUMIFS(Table4[Loan Amount],Table4[Loan Payment Start Date],"<"&Table5[[#This Row],[Payment date]]) - SUM($S$5:$S13) - SUM($W$5:W13))*InterestRate*(Table5[[#This Row],[Payment date]] - IF($E$14="End of Month",EOMONTH(Table5[[#This Row],[Payment date]],-1), IF($E$14="Mid of Month",EOMONTH(Table5[[#This Row],[Payment date]],-2)+15, IF($E$14="Start of Month",EOMONTH(Table5[[#This Row],[Payment date]],-2) + 1))) )/360) + (SUM(IFERROR((IF(Table4[Loan Payment Start Date]=Table5[[#This Row],[Payment date]],Table4[Loan Amount],"")*(Table4[Loan Payment Start Date]-Table4[Loan Date])*InterestRate/360),0),0)),"")} -> 2.2555469e-13 | U14: =IF(Table5[[#This Row],[Payment date]]<>"",SUMIFS(Table4[[#All],[Loan Amount]],Table4[[#All],[Loan Payment Start Date]],"="&Table5[[#This Row],[Payment date]])*($E$7),"") -> 0 | V14: {=IF(Table5[[#This Row],[Payment date]]<>"",IF(Table5[[#This Row],[Payment date]]=MIN(Table4[[#All],[Loan Payment Start Date]]),$E$8+$E$10*LoanAmount,0) + IF(Table5[[#This Row],[Payment date]] =MIN(_xlfn._xlws.FILTER(Table5[Payment date],(Table5[Payment date]>=EDATE(LoanStartDate,12*DATEDIF(LoanStartDate,Table5[[#This Row],[Payment date]],"y")))*(Table5[Beginning balance]<>0))), $E$9*LoanAmount,0),"")} -> 0 | Y14: =IF(Table5[[#This Row],[Payment date]]<>"",(SUMIFS(Table4[Loan Amount],Table4[Loan Payment Start Date],"<="&Table5[[#This Row],[Payment date]]) - SUM($S$5:$S13) - - SUM($W$5:W13))*Table5[[#This Row],[Delay in Payment ]]*($E$16+ InterestRate)/365,"") -> 0 | Z14: =IF(Table5[[#This Row],[Payment date]]<>"",Table5[[#This Row],[Payment date]]+Table5[[#This Row],[Delay in Payment ]],"") -> 45597 | AA14: =IF(Table5[[#This Row],[Payment date]]<>"",Table5[[#This Row],[Beginning balance]]-Table5[[#This Row],[Principal Payment]] - Table5[[#This Row],[Extra Payment]],"") -> 1.4551915e-11 | AB14: =IF(Table5[[#This Row],[Payment date]]<>"",Table5[[#This Row],[Draw Fee]]+Table5[[#This Row],[Interest]]+Table5[[#This Row],[Principal Payment]]+Table5[[#This Row],[Overdue Interest]],"") -> 2.2555469e-13
